Workbook
Name Param_Quarter: Parameters!$C$5
Name Param_Dominant: Parameters!$C$8
Name Param_Mixed: Parameters!$C$9
Name Param_FWA: Parameters!$C$10
Name Param_Fiber: Parameters!$C$11
Name Param_Satellite: Parameters!$C$12
Name Param_Coequal: Parameters!$C$13
Name Param_CoreShare: Parameters!$C$14
Name Param_RateSkew: Parameters!$C$15
Name Param_TwoQ: Parameters!$C$16
Name Param_TrackerExists: Parameters!$C$17
Name Param_CMCSA_On: Parameters!$C$18
Name Param_InputMode: Parameters!$C$19
Name Param_CommitExcess: Parameters!$C$22
Name Dash_Print: Dashboard!$C$8

Sheet Dashboard
B1: CHARTER REC 1 · ATTRIBUTION DIAGNOSTIC
B2: =IF(C15="","Fill the quarterly net-loss tracker first — attribution cells are empty on purpose.",C15)
B3: =CONCATENATE("Selected: ",Parameters!C5," · Units: residential Internet customers · "&"Yellow INPUT on Net-loss tracker / Attribution / Segments · "&"Public spine: Ex99.1 Q1 2026 res. Internet −117,000 · Q2 2026 −166,000 (RETRIEVED) · "&"Template — not a filled mix")
B5: Res. Internet print | E5: vs Comcast (same quarter) | H5: Excess vs peer rate | K5: Largest reason
B6: ='Net-loss tracker'!B37 | E6: =IF(OR(Parameters!C18="No",'Net-loss tracker'!B40=""),"n/a",'Net-loss tracker'!B40) | H6: =IF(OR(Parameters!C18="No",'Net-loss tracker'!B46=""),"n/a",'Net-loss tracker'!B46) | K6: =IF(Attribution!C49="No","EMPTY",Attribution!D48)
B7: ='Net-loss tracker'!B48 | E7: ="CMCSA resid. BB" | H7: ="Q1 playbook commit 54k" | K7: =IF(Attribution!C49="No","do not fire a play",TEXT(Attribution!C48,"0% of disconnects"))
B9: DIAGNOSIS PANEL · thresholds live on Parameters (ESTIMATED defaults)
B10: Test | C10: Read | K10: Light
B11: G1 tracker | C11: =Parameters!C17 | K11: =IF(LEFT(Parameters!C17,3)="Yes","SKIP BUILD","FILL FIRST")
B12: Dominant driver (pptx >= P4) | C12: =IF(Attribution!C49="No","EMPTY — no reason fill",IF(Attribution!C48>=Parameters!C8,"DOMINANT — "&Attribution!D48&" holds "&TEXT(Attribution!C48,"0%")&" (>= "&TEXT(Parameters!C8,"0%")&")",IF(Attribution!C48>=Parameters!C9,"MIXED — largest is "&TEXT(Attribution!C48,"0%")&" (25-40% band). Run top two as experiments.","NULL — no cohort >= "&TEXT(Parameters!C9,"0%")&". Scenario 6 fires."))) | K12: =IF(Attribution!C49="No","EMPTY",IF(Attribution!C48>=Parameters!C8,"RED — fire one play",IF(Attribution!C48>=Parameters!C9,"AMBER — experiment","GREEN — null / S6")))
B13: Scenario routed | C13: =C16 | K13: =IF(Attribution!C49="No","HOLD","SEE PLAYBOOK")
B14: WHERE / WHO flag | C14: =Segments!C78 | K14: =IF(LEFT(Segments!C78,5)="EMPTY","EMPTY","READ")
B15: Takeaway (engine) | C15: =IF(Attribution!C49="No","Fill the quarterly net-loss tracker first — attribution cells are empty on purpose.",IF(Attribution!C48>=Parameters!C8,Attribution!D48&" accounts for "&TEXT(Attribution!C48,"0%")&" of disconnects — above the "&TEXT(Parameters!C8,"0%")&" dominant-driver gate. Fire that one play on the core.",IF(Attribution!C48>=Parameters!C9,"Mixed picture: "&Attribution!D48&" is largest at "&TEXT(Attribution!C48,"0%")&" but below "&TEXT(Parameters!C8,"0%")&". Run the top two as controlled experiments.","No dominant driver — no cohort reaches "&TEXT(Parameters!C9,"0%")&" of disconnects. Scenario 6 (null) is the recommendation, not a guess.")))
B16: Scenario (engine) | C16: =IF(Attribution!C49="No","HOLD — empty cells. The playbook does not fire.",IF(AND(INDEX(Attribution!D40:D45,1)>=Parameters!C10,N(Segments!D71)>=0.3),"S1 FWA-driven — convergence pricing in FWA zones (kill: no churn split in 2 qtrs / negative bundle margin)",IF(INDEX(Attribution!D40:D45,2)>=Parameters!C11,"S2 Fiber-driven — re-sequence evolution on overlap + symmetric win-back (kill: completed zones bleed at same rate)",IF(INDEX(Attribution!D40:D45,3)>=Parameters!C12,"S3 Satellite-driven — accelerate rural activation (kill: new-passing penetration below underwriting)",IF(INDEX(Attribution!D40:D45,4)>=Parameters!C9,"S4 Housing / move-out — mover capture, not a save-offer (kill: port-out data contradicts the macro story)",IF(INDEX(Attribution!D40:D45,5)>=Parameters!C9,"S5 Non-pay — value tier at delinquency (kill: save-rate economics below LTV)",IF(Attribution!C48<Parameters!C9,"S6 Null — no dominant driver. Market-layer disclosure + spend-capped experiments.","Largest cell is "&Attribution!D48&" — apply the matching lead play; do not fire two expensive levers."))))))
B18: =IF(Attribution!C49="No","Reason contribution is empty — fill Attribution before this chart can make a claim","Largest leak is "&Attribution!D48&" at "&TEXT(Attribution!C48,"0%")&" of sampled disconnects · gray = the rest · accent = the story bar")
B19: Reason (sorted) | C19: Disconnects | D19: Share | E19: Rest | F19: Largest
B20: =Attribution!B54 | C20: =Attribution!C54 | D20: =Attribution!D54 | E20: =Attribution!E54 | F20: =Attribution!F54
B21: =Attribution!B55 | C21: =Attribution!C55 | D21: =Attribution!D55 | E21: =Attribution!E55 | F21: =Attribution!F55
B22: =Attribution!B56 | C22: =Attribution!C56 | D22: =Attribution!D56 | E22: =Attribution!E56 | F22: =Attribution!F56
B23: =Attribution!B57 | C23: =Attribution!C57 | D23: =Attribution!D57 | E23: =Attribution!E57 | F23: =Attribution!F57
B24: =Attribution!B58 | C24: =Attribution!C58 | D24: =Attribution!D58 | E24: =Attribution!E58 | F24: =Attribution!F58
B25: =Attribution!B59 | C25: =Attribution!C59 | D25: =Attribution!D59 | E25: =Attribution!E59 | F25: =Attribution!F59
B26: =Attribution!B60 | C26: =Attribution!C60 | D26: =Attribution!D60 | E26: =Attribution!E60 | F26: =Attribution!F60
B27: Source: Attribution A1-A7 (user-entered counts) · Residual is derived · Bars begin at zero · One accent (largest) vs gray · Not a pie
B29: =IF('Net-loss tracker'!J11="","Residential Internet print — public spine only until internals fill","Charter residential Internet stayed worse than Comcast in every quarter both prints exist")
B30: Quarter | C30: Q1 2024 | D30: Q2 2024 | E30: Q3 2024 | F30: Q4 2024 | G30: Q1 2025 | H30: Q2 2025 | I30: Q3 2025 | J30: Q4 2025 | K30: Q1 2026 | L30: Q2 2026 | M30: Q3 2026 | N30: Q4 2026
B31: CHTR res. Internet | C31: =IF('Net-loss tracker'!E11="",NA(),'Net-loss tracker'!E11) | D31: =IF('Net-loss tracker'!F11="",NA(),'Net-loss tracker'!F11) | E31: =IF('Net-loss tracker'!G11="",NA(),'Net-loss tracker'!G11) | F31: =IF('Net-loss tracker'!H11="",NA(),'Net-loss tracker'!H11) | G31: =IF('Net-loss tracker'!I11="",NA(),'Net-loss tracker'!I11) | H31: =IF('Net-loss tracker'!J11="",NA(),'Net-loss tracker'!J11) | I31: =IF('Net-loss tracker'!K11="",NA(),'Net-loss tracker'!K11) | J31: =IF('Net-loss tracker'!L11="",NA(),'Net-loss tracker'!L11) | ... N31: =IF('Net-loss tracker'!P11="",NA(),'Net-loss tracker'!P11)
B32: CMCSA resid. BB | C32: =IF('Net-loss tracker'!E14="",NA(),'Net-loss tracker'!E14) | D32: =IF('Net-loss tracker'!F14="",NA(),'Net-loss tracker'!F14) | E32: =IF('Net-loss tracker'!G14="",NA(),'Net-loss tracker'!G14) | F32: =IF('Net-loss tracker'!H14="",NA(),'Net-loss tracker'!H14) | G32: =IF('Net-loss tracker'!I14="",NA(),'Net-loss tracker'!I14) | H32: =IF('Net-loss tracker'!J14="",NA(),'Net-loss tracker'!J14) | I32: =IF('Net-loss tracker'!K14="",NA(),'Net-loss tracker'!K14) | J32: =IF('Net-loss tracker'!L14="",NA(),'Net-loss tracker'!L14) | ... N32: =IF('Net-loss tracker'!P14="",NA(),'Net-loss tracker'!P14)
B33: Excess vs CMCSA rate | C33: =IF('Net-loss tracker'!E20="",NA(),'Net-loss tracker'!E20) | D33: =IF('Net-loss tracker'!F20="",NA(),'Net-loss tracker'!F20) | E33: =IF('Net-loss tracker'!G20="",NA(),'Net-loss tracker'!G20) | F33: =IF('Net-loss tracker'!H20="",NA(),'Net-loss tracker'!H20) | G33: =IF('Net-loss tracker'!I20="",NA(),'Net-loss tracker'!I20) | H33: =IF('Net-loss tracker'!J20="",NA(),'Net-loss tracker'!J20) | I33: =IF('Net-loss tracker'!K20="",NA(),'Net-loss tracker'!K20) | J33: =IF('Net-loss tracker'!L20="",NA(),'Net-loss tracker'!L20) | ... N33: =IF('Net-loss tracker'!P20="",NA(),'Net-loss tracker'!P20)
K34: Axis note: line chart may zoom off zero because the story is movement in a tight negative band. Bars on this sheet still start at zero.
B48: KILL RULES AND UNWILLING-TO-CLAIM · written before the recommendation
B49: # | C49: Rule (from pptx + six-recommendation-areas / decisions.md) | K49: This quarter
B50: K1 | C50: Tracker already exists and is used quarterly -> skip Area 1 build; go to mix control. | K50: =IF(LEFT(Parameters!C17,3)="Yes","KILL — skip G1 build","OPEN — fill G1")
B51: K2 | C51: Fill shows move-out matching Comcast -> kill Area 2 as a Charter-specific print; Area 6 becomes the CEO-charge answer. Do not add rural miles. | K51: =IF(OR(Attribution!C49="No",'Net-loss tracker'!B46=""),"UNTESTED",IF(AND(Attribution!D48=Parameters!B29,'Net-loss tracker'!B46<=0),"KILL Area 2 — move-out / no excess","OPEN")
B52: K3 | C52: Do not fire two expensive levers in the same quarter. Co-equal cells: cheaper first (Parameters P9). | K52: =IF(AND(Attribution!C49="Yes",Attribution!C50>=Parameters!C9,ABS(Attribution!C48-Attribution!C50)<=Parameters!C13),"CO-EQUAL — fire the cheaper lever only","OK")
B53: K4 | C53: Do not treat call-center reason codes as the trigger. Sample the disconnect (pptx slide 4). | K53: PROCESS — not a cell
B54: K5 | C54: Do not add rural miles to fix a core leak. Do not fire company-wide upgrade/rebuild as the default to move-out, FWA, nonpay, or off-overlap. | K54: =IF(LEFT(Segments!C79,4)="Core","CORE — no rural miles",IF(LEFT(Segments!C78,5)="EMPTY","UNTESTED","READ F2"))
B55: K6 | C55: PPTX interlock: two consecutive quarters before full-scale (experiments may start on one). | K55: =IF(Parameters!C16="Yes","ARMED — full-scale needs 2 qtrs","OFF")
B56: K7 | C56: Unwilling to claim: a filled mix, a gross churn rate, that -66k re-rates five-year ~80%, that mobile offsets Internet, that 54k sits in any one cell until the first fill. | K56: STANDING
B58: Print-friendly: this sheet is the exhibit. Backup arithmetic lives on Net-loss tracker, Attribution, Segments, Assumptions. Do not present empty attribution cells as a measured mix. Title (row 2) updates from formulas when numbers are pasted.

Sheet Cover
A1: COVER · HOW TO USE THIS TEMPLATE
A2: A diagnostic template for privatized / internal numbers. It is not a filled Charter mix and it does not fire Rec 1 from empty cells.
A4: What this is
A5: Job | B5: Rec 1 sensor + playbook from CHTR_Rec1_AttributionPlaybook.pptx, wired to the G1 quarterly net-loss tracker language in Decisions/six-recommendation-areas.md and Decisions/decisions.md. Charter (or the case team) pastes internals; Excel diagnoses them.
A6: What it is not | B6: Not a study. Not invented quarterly net-adds presented as Ex99.1. Not a reason play you can take to the CEO while Attribution is empty. Not a password-locked model.
A8: Color and tags
A9: Yellow + blue font | B9: INPUT — user-entered privatized / internal. Unlock these; type over them.
A10: Green | B10: RETRIEVED — public Ex99.1 / trending / CMCSA Ex99.1. Prefill is a citation, not an attribution.
A11: Blue fill | B11: ESTIMATED — template default thresholds from the pptx (40 / 25 / 35). Change them on Parameters before go-live.
A12: Gray | B12: DERIVED — Excel formula. Do not overwrite. Recompute happens in the workbook, not in this cover.
A14: How the user fills it
A15: 1. Parameters | B15: Set the selected quarter (default Q1 2026 — the assignment anchor; Q2 is a later public fact). Answer tracker already exists? If yes, skip the G1 build. Confirm Comcast benchmark on, and leave thresholds at pptx defaults unless the executive team ratifies new ones.
A16: 2. Net-loss tracker first | B16: Paste beginning residential Internet PSUs, gross adds, and disconnects in yellow. Net is a formula (T2 - T3). Public prints are already filled where Ex99.1 exists (Q1 2026 -117,000; Q2 2026 -166,000). Do not invent internals to match them. Comcast Q1 -65,000 / begin 28,719,000 is filled; other Comcast quarters stay blank.
A17: 3. Attribution | B17: Paste sampled disconnect COUNTS by cause-cohort (FWA, fiber, satellite, move-out, non-pay, service/other). Not agent codes. Residual is a formula against tracker disconnects. Exposure-class counts (and optional begin PSUs) test the pptx sensor vs the uncontested control.
A18: 4. Segments | B18: Paste WHERE (core / rural / AT&T / Verizon / rest) and WHO (tenure, product at leave, ARPU, audited exit signal). 27% / 16% are footprint mix — do not paste them as losses. Rural CR +41k is not the rural Internet cut.
A19: 5. Read Dashboard only after 2-4 | B19: Row 2 is the takeaway (formula). Traffic lights apply pptx 40 / 25 / 35 gates. One accent bar vs gray. Kill rules sit on the same page. If Attribution is empty, the title will tell you to fill the tracker first — believe it.
A21: Sheet map
A22: Dashboard | B22: Print-first exhibit. Formula titles, KPIs, reason bars, CHTR vs CMCSA line, diagnosis, kill rules.
A23: Cover | B23: This page.
A24: Net-loss tracker | B24: G1. Quarters as columns. Internals yellow; public prints green; net / rates / excess formulas.
A25: Attribution | B25: Reason counts, residual, shares, contribution, exposure class, sorted chart feed.
A26: Segments | B26: WHERE / WHO input grids + flags (core vs rural, overlap, tenure, exit signal).
A27: Parameters | B27: Quarter, taxonomy, thresholds, Comcast toggle, highlight hex, dropdowns.
A28: Assumptions | B28: One line per input, ID, RETRIEVED vs INPUT vs ESTIMATED, source.
A29: Playbook | B29: Six pptx scenarios + GAP R1-R4: trigger, play, economics gate, proof, kill, fallback. Reference only.
A31: Public figures prefilled (RETRIEVED)
A32: Residential Internet | B32: Q1 2026 -117,000 · Q2 2026 -166,000 · plus 2024-2025 quarterly prints from the Q1 trending schedule. Company Internet -120,000 / -172,000 is context only.
A33: Begin PSUs | B33: Q1 2026 begin 27,641,000 (YE2025 EOP). Other begins from trending EOP identity. Overwrite if the internal census differs.
A34: Comcast | B34: Q1 2026 domestic residential BB -65,000; begin 28,719,000. Excess vs that rate is the 54k identity (commit 54,000, round down from 54.4k) — cited from six-recommendation-areas.md / network_churn_model.py, not the pptx.
A36: Could not map from the pptx alone
A37: See return note | B37: The pptx does not specify the G1 grid, the 54k Comcast excess, product-mix-at-leave, or a numeric satellite threshold. Those come from six-recommendation-areas.md / decisions.md (labeled). MVNO wholesale cost, LTV gates, port-out carrier shares, BDC location joins, and treatment/control results are open client items (pptx slide 12) — they are not fake-filled here.
A39: Question for the client
A40: Binary

Sheet Net-loss tracker
A1: G1 · QUARTERLY NET-LOSS TRACKER — fill this first
A2: six-recommendation-areas.md: “Fill the quarterly net-loss tracker first.” Unit = residential Internet. Prefer gross adds vs disconnects so net is a formula. Yellow = Charter internals (INPUT). Green = public Ex99.1 / trending (RETRIEVED). Do not treat rural CR +41k / +47k as this Internet cut. Do not fire a reason play from empty cells.
A5: ID | B5: Line | C5: Tag | D5: Source / formula | E5: Q1 2024 | F5: Q2 2024 | G5: Q3 2024 | H5: Q4 2024 | I5: Q1 2025 | J5: Q2 2025 | K5: Q3 2025 | L5: Q4 2025 | M5: Q1 2026 | N5: Q2 2026 | O5: Q3 2026 | P5: Q4 2026
A6: T1 | B6: Beginning residential Internet PSUs | C6: see cells | D6: Prior-quarter EOP. Prefill = trending identity (RETRIEVED). Overwrite if internal census differs. | E6: 28544000 | F6: 28472000 | G6: 28318000 | H6: 28205000 | I6: 28034000 | J6: 27979000 | K6: 27868000 | L6: 27760000 | M6: 27641000 | N6: 27524000
A7: T2 | B7: Gross adds (internal) | C7: INPUT | D7: Not disclosed. Leave blank until the tracker exists. Sampled, not a guess.
A8: T3 | B8: Disconnects (internal) | C8: INPUT | D8: Not disclosed. Sample the disconnect — do not paste agent codes as the file (pptx slide 4).
A9: T4 | B9: Internal net adds = T2 − T3 | C9: DERIVED | D9: Blank until both T2 and T3 are filled. Zero is not a fill. | E9: =IF(OR(E7="",E8=""),"",E7-E8) | F9: =IF(OR(F7="",F8=""),"",F7-F8) | G9: =IF(OR(G7="",G8=""),"",G7-G8) | H9: =IF(OR(H7="",H8=""),"",H7-H8) | I9: =IF(OR(I7="",I8=""),"",I7-I8) | J9: =IF(OR(J7="",J8=""),"",J7-J8) | K9: =IF(OR(K7="",K8=""),"",K7-K8) | L9: =IF(OR(L7="",L8=""),"",L7-L8) | ... P9: =IF(OR(P7="",P8=""),"",P7-P8)
A10: T5 | B10: Public print — res. Internet net adds (Ex99.1) | C10: RETRIEVED | D10: CHTR Ex99.1 / Q1 trending. Q1 2026 = −117,000. Q2 2026 = −166,000. FY columns omitted. | E10: -72000 | F10: -154000 | G10: -113000 | H10: -171000 | I10: -55000 | J10: -111000 | K10: -108000 | L10: -119000 | M10: -117000 | N10: -166000
A11: T6 | B11: Print used for diagnosis | C11: DERIVED | D11: Internal net if T2 and T3 filled; else public print. Never invent a mix on top of this. | E11: =IF(E9<>"",E9,IF(E10<>"",E10,"")) | F11: =IF(F9<>"",F9,IF(F10<>"",F10,"")) | G11: =IF(G9<>"",G9,IF(G10<>"",G10,"")) | H11: =IF(H9<>"",H9,IF(H10<>"",H10,"")) | I11: =IF(I9<>"",I9,IF(I10<>"",I10,"")) | J11: =IF(J9<>"",J9,IF(J10<>"",J10,"")) | K11: =IF(K9<>"",K9,IF(K10<>"",K10,"")) | L11: =IF(L9<>"",L9,IF(L10<>"",L10,"")) | ... P11: =IF(P9<>"",P9,IF(P10<>"",P10,""))
A12: T7 | B12: Company Internet net adds (context, not this cut) | C12: RETRIEVED | D12: Ex99.1 total Internet. Q1 2026 −120,000 · Q2 2026 −172,000. Includes SMB. | E12: -72000 | F12: -148000 | G12: -110000 | H12: -177000 | I12: -59000 | J12: -116000 | K12: -109000 | L12: -119000 | M12: -120000 | N12: -172000
A13: T8 | B13: Rural CR net adds (NOT an Internet cut) | C13: RETRIEVED | D13: Ex99.1 rural-footprint customer relationships. Q1 +41,000 · Q2 +47,000. Do not use as T6. | M13: 41000 | N13: 47000
A14: T9 | B14: Comcast domestic resid. BB net adds | C14: see cells | D14: Q1 2026 −65,000 RETRIEVED (CMCSA Ex99.1). Other quarters INPUT. Leave blank if unused. | M14: -65000
A15: T10 | B15: Comcast resid. BB beginning PSUs | C15: see cells | D15: Q1 2026 28,719,000 = 28,654k EOP − (−65k). Other quarters INPUT. | M15: 28719000
A16: T11 | B16: Comcast net-loss rate = |T9| / T10 | C16: DERIVED | D16: Only when T9 and T10 are filled. | E16: =IF(OR(E14="",E15="",E15=0),"",ABS(E14)/E15) | F16: =IF(OR(F14="",F15="",F15=0),"",ABS(F14)/F15) | G16: =IF(OR(G14="",G15="",G15=0),"",ABS(G14)/G15) | H16: =IF(OR(H14="",H15="",H15=0),"",ABS(H14)/H15) | I16: =IF(OR(I14="",I15="",I15=0),"",ABS(I14)/I15) | J16: =IF(OR(J14="",J15="",J15=0),"",ABS(J14)/J15) | K16: =IF(OR(K14="",K15="",K15=0),"",ABS(K14)/K15) | L16: =IF(OR(L14="",L15="",L15=0),"",ABS(L14)/L15) | ... P16: =IF(OR(P14="",P15="",P15=0),"",ABS(P14)/P15)
A17: T12 | B17: Charter res. net-loss rate = |T6| / T1 | C17: DERIVED | D17: Net-loss rate, not gross churn. Gross churn is unused because it is not disclosed. | E17: =IF(OR(E11="",E6="",E6=0),"",ABS(E11)/E6) | F17: =IF(OR(F11="",F6="",F6=0),"",ABS(F11)/F6) | G17: =IF(OR(G11="",G6="",G6=0),"",ABS(G11)/G6) | H17: =IF(OR(H11="",H6="",H6=0),"",ABS(H11)/H6) | I17: =IF(OR(I11="",I6="",I6=0),"",ABS(I11)/I6) | J17: =IF(OR(J11="",J6="",J6=0),"",ABS(J11)/J6) | K17: =IF(OR(K11="",K6="",K6=0),"",ABS(K11)/K6) | L17: =IF(OR(L11="",L6="",L6=0),"",ABS(L11)/L6) | ... P17: =IF(OR(P11="",P6="",P6=0),"",ABS(P11)/P6)
A18: T13 | B18: Rate ratio vs Comcast = T12 / T11 | C18: DERIVED | D18: Q1 playbook commit 1.8× (round down from 1.87×). | E18: =IF(OR(E16="",E17="",E16=0),"",E17/E16) | F18: =IF(OR(F16="",F17="",F16=0),"",F17/F16) | G18: =IF(OR(G16="",G17="",G16=0),"",G17/G16) | H18: =IF(OR(H16="",H17="",H16=0),"",H17/H16) | I18: =IF(OR(I16="",I17="",I16=0),"",I17/I16) | J18: =IF(OR(J16="",J17="",J16=0),"",J17/J16) | K18: =IF(OR(K16="",K17="",K16=0),"",K17/K16) | L18: =IF(OR(L16="",L17="",L16=0),"",L17/L16) | ... P18: =IF(OR(P16="",P17="",P16=0),"",P17/P16)
A19: T14 | B19: Expected CHTR losses at CMCSA rate = T11 × T1 | C19: DERIVED | D19: Build 2 in ifxy-stock-signal.md / network_churn_model.py. | E19: =IF(OR(E16="",E6=""),"",E16*E6) | F19: =IF(OR(F16="",F6=""),"",F16*F6) | G19: =IF(OR(G16="",G6=""),"",G16*G6) | H19: =IF(OR(H16="",H6=""),"",H16*H6) | I19: =IF(OR(I16="",I6=""),"",I16*I6) | J19: =IF(OR(J16="",J6=""),"",J16*J6) | K19: =IF(OR(K16="",K6=""),"",K16*K6) | L19: =IF(OR(L16="",L6=""),"",L16*L6) | ... P19: =IF(OR(P16="",P6=""),"",P16*P6)
A20: T15 | B20: Excess vs Comcast = |T6| − T14 | C20: DERIVED | D20: Q1 identity ≈ 54.4k; playbook commits 54k (Parameters P18). Cite six-recommendation-areas.md. | E20: =IF(OR(E11="",E19=""),"",ABS(E11)-E19) | F20: =IF(OR(F11="",F19=""),"",ABS(F11)-F19) | G20: =IF(OR(G11="",G19=""),"",ABS(G11)-G19) | H20: =IF(OR(H11="",H19=""),"",ABS(H11)-H19) | I20: =IF(OR(I11="",I19=""),"",ABS(I11)-I19) | J20: =IF(OR(J11="",J19=""),"",ABS(J11)-J19) | K20: =IF(OR(K11="",K19=""),"",ABS(K11)-K19) | L20: =IF(OR(L11="",L19=""),"",ABS(L11)-L19) | ... P20: =IF(OR(P11="",P19=""),"",ABS(P11)-P19)
A21: T16 | B21: Ending PSUs = T1 + T6 | C21: DERIVED | D21: Identity check vs trending EOP when public print is used. | E21: =IF(OR(E6="",E11=""),"",E6+E11) | F21: =IF(OR(F6="",F11=""),"",F6+F11) | G21: =IF(OR(G6="",G11=""),"",G6+G11) | H21: =IF(OR(H6="",H11=""),"",H6+H11) | I21: =IF(OR(I6="",I11=""),"",I6+I11) | J21: =IF(OR(J6="",J11=""),"",J6+J11) | K21: =IF(OR(K6="",K11=""),"",K6+K11) | L21: =IF(OR(L6="",L11=""),"",L6+L11) | ... P21: =IF(OR(P6="",P11=""),"",P6+P11)
A22: T17 | B22: Internal vs public reconcile | C22: DERIVED | D22: OK if internals blank or match public print; FLAG if they differ. | E22: =IF(E9="",IF(E10="","PLACEHOLDER — no print","Public print only — internals empty"),IF(E10="","Internal only",IF(ABS(E9-E10)<500,"OK — internal matches public","FLAG — internal ≠ public print"))) | F22: =IF(F9="",IF(F10="","PLACEHOLDER — no print","Public print only — internals empty"),IF(F10="","Internal only",IF(ABS(F9-F10)<500,"OK — internal matches public","FLAG — internal ≠ public print"))) | G22: =IF(G9="",IF(G10="","PLACEHOLDER — no print","Public print only — internals empty"),IF(G10="","Internal only",IF(ABS(G9-G10)<500,"OK — internal matches public","FLAG — internal ≠ public print"))) | H22: =IF(H9="",IF(H10="","PLACEHOLDER — no print","Public print only — internals empty"),IF(H10="","Internal only",IF(ABS(H9-H10)<500,"OK — internal matches public","FLAG — internal ≠ public print"))) | I22: =IF(I9="",IF(I10="","PLACEHOLDER — no print","Public print only — internals empty"),IF(I10="","Internal only",IF(ABS(I9-I10)<500,"OK — internal matches public","FLAG — internal ≠ public print"))) | J22: =IF(J9="",IF(J10="","PLACEHOLDER — no print","Public print only — internals empty"),IF(J10="","Internal only",IF(ABS(J9-J10)<500,"OK — internal matches public","FLAG — internal ≠ public print"))) | K22: =IF(K9="",IF(K10="","PLACEHOLDER — no print","Public print only — internals empty"),IF(K10="","Internal only",IF(ABS(K9-K10)<500,"OK — internal matches public","FLAG — internal ≠ public print"))) | L22: =IF(L9="",IF(L10="","PLACEHOLDER — no print","Public print only — internals empty"),IF(L10="","Internal only",IF(ABS(L9-L10)<500,"OK — internal matches public","FLAG — internal ≠ public print"))) | ... P22: =IF(P9="",IF(P10="","PLACEHOLDER — no print","Public print only — internals empty"),IF(P10="","Internal only",IF(ABS(P9-P10)<500,"OK — internal matches public","FLAG — internal ≠ public print")))
A24: HOW TO READ THIS SHEET
A25: 1. Paste starting PSUs / gross adds / disconnects in yellow. Net (T4) and print used (T6) are formulas.
A26: 2. Public −117,000 (Q1 2026) and −166,000 (Q2 2026) are RETRIEVED Ex99.1 residential Internet — not a filled attribution.
A27: 3. Excess vs Comcast (T15) is the 54k figure’s identity for Q1 only (CMCSA rate × CHTR begin − |print|). Other quarters compute only when Comcast cells are filled.
A28: 4. Rural CR is on this sheet so nobody confuses +41k / +47k with residential Internet. It is not T6.
A29: 5. Kill: if Parameters says the tracker already exists, skip building G1 — paste the last eight quarters and go to Attribution.
A31: Selected-quarter pull (engine — do not edit)
A32: Begin PSUs | B32: =IFERROR(INDEX('Net-loss tracker'!$E$6:$P$6,MATCH(Param_Quarter,'Net-loss tracker'!$E$5:$P$5,0)),"")
A33: Gross adds | B33: =IFERROR(INDEX('Net-loss tracker'!$E$7:$P$7,MATCH(Param_Quarter,'Net-loss tracker'!$E$5:$P$5,0)),"")
A34: Disconnects | B34: =IFERROR(INDEX('Net-loss tracker'!$E$8:$P$8,MATCH(Param_Quarter,'Net-loss tracker'!$E$5:$P$5,0)),"")
A35: Internal net | B35: =IFERROR(INDEX('Net-loss tracker'!$E$9:$P$9,MATCH(Param_Quarter,'Net-loss tracker'!$E$5:$P$5,0)),"")
A36: Public print | B36: =IFERROR(INDEX('Net-loss tracker'!$E$10:$P$10,MATCH(Param_Quarter,'Net-loss tracker'!$E$5:$P$5,0)),"")
A37: Print used | B37: =IFERROR(INDEX('Net-loss tracker'!$E$11:$P$11,MATCH(Param_Quarter,'Net-loss tracker'!$E$5:$P$5,0)),"")
A38: Company Internet | B38: =IFERROR(INDEX('Net-loss tracker'!$E$12:$P$12,MATCH(Param_Quarter,'Net-loss tracker'!$E$5:$P$5,0)),"")
A39: Rural CR | B39: =IFERROR(INDEX('Net-loss tracker'!$E$13:$P$13,MATCH(Param_Quarter,'Net-loss tracker'!$E$5:$P$5,0)),"")
A40: CMCSA net | B40: =IFERROR(INDEX('Net-loss tracker'!$E$14:$P$14,MATCH(Param_Quarter,'Net-loss tracker'!$E$5:$P$5,0)),"")
A41: CMCSA begin | B41: =IFERROR(INDEX('Net-loss tracker'!$E$15:$P$15,MATCH(Param_Quarter,'Net-loss tracker'!$E$5:$P$5,0)),"")
A42: CMCSA rate | B42: =IFERROR(INDEX('Net-loss tracker'!$E$16:$P$16,MATCH(Param_Quarter,'Net-loss tracker'!$E$5:$P$5,0)),"")
A43: CHTR rate | B43: =IFERROR(INDEX('Net-loss tracker'!$E$17:$P$17,MATCH(Param_Quarter,'Net-loss tracker'!$E$5:$P$5,0)),"")
A44: Rate ratio | B44: =IFERROR(INDEX('Net-loss tracker'!$E$18:$P$18,MATCH(Param_Quarter,'Net-loss tracker'!$E$5:$P$5,0)),"")
...

Sheet Attribution
A1: ATTRIBUTION · REASON PLAY — sampled disconnects, not agent codes
A2: PPTX cause-cohorts: FWA-covered · fiber-overbuilt · satellite-only · housing/move-out · non-pay · residual. GAP R1–R4 maps onto the same rows (satellite is pptx-only). Enter COUNTS of sampled disconnects (yellow). Residual is a formula. Empty cells are on purpose — the playbook will not fire from a guess.
A5: ID | B5: Cause-cohort (label from Parameters) | C5: Tag | D5: PPTX / GAP | E5: Q1 2024 | F5: Q2 2024 | G5: Q3 2024 | H5: Q4 2024 | I5: Q1 2025 | J5: Q2 2025 | K5: Q3 2025 | L5: Q4 2025 | M5: Q1 2026 | N5: Q2 2026 | O5: Q3 2026 | P5: Q4 2026
A6: A1 | B6: =Parameters!B26 | C6: INPUT | D6: S1 / R2
A7: A2 | B7: =Parameters!B27 | C7: INPUT | D7: S2 / R3
A8: A3 | B8: =Parameters!B28 | C8: INPUT | D8: S3 / W2
A9: A4 | B9: =Parameters!B29 | C9: INPUT | D9: S4 / R1
A10: A5 | B10: =Parameters!B30 | C10: INPUT | D10: S5 / R4
A11: A6 | B11: =Parameters!B31 | C11: INPUT | D11: Residual
A12: A7 | B12: Residual (tracker disconnects − sum of A1–A6) | C12: DERIVED | D12: Largest residual is a data-quality flag | E12: =IF(E14="","",E14-SUM(E6:E11)) | F12: =IF(F14="","",F14-SUM(F6:F11)) | G12: =IF(G14="","",G14-SUM(G6:G11)) | H12: =IF(H14="","",H14-SUM(H6:H11)) | I12: =IF(I14="","",I14-SUM(I6:I11)) | J12: =IF(J14="","",J14-SUM(J6:J11)) | K12: =IF(K14="","",K14-SUM(K6:K11)) | L12: =IF(L14="","",L14-SUM(L6:L11)) | ... P12: =IF(P14="","",P14-SUM(P6:P11))
A13: A8 | B13: Sum of entered reason counts (A1–A6) | C13: DERIVED | D13: Does not include residual | E13: =IF(COUNT(E6:E11)=0,"",SUM(E6:E11)) | F13: =IF(COUNT(F6:F11)=0,"",SUM(F6:F11)) | G13: =IF(COUNT(G6:G11)=0,"",SUM(G6:G11)) | H13: =IF(COUNT(H6:H11)=0,"",SUM(H6:H11)) | I13: =IF(COUNT(I6:I11)=0,"",SUM(I6:I11)) | J13: =IF(COUNT(J6:J11)=0,"",SUM(J6:J11)) | K13: =IF(COUNT(K6:K11)=0,"",SUM(K6:K11)) | L13: =IF(COUNT(L6:L11)=0,"",SUM(L6:L11)) | ... P13: =IF(COUNT(P6:P11)=0,"",SUM(P6:P11))
A14: A9 | B14: Tracker disconnects (T3) — or |print| placeholder | C14: DERIVED | D14: If T3 blank and mode is Percent, uses |T6| and labels PLACEHOLDER | E14: =IF('Net-loss tracker'!E8<>"",'Net-loss tracker'!E8,IF(AND(Parameters!$C$19="Percent",'Net-loss tracker'!E11<>""),ABS('Net-loss tracker'!E11),"")) | F14: =IF('Net-loss tracker'!F8<>"",'Net-loss tracker'!F8,IF(AND(Parameters!$C$19="Percent",'Net-loss tracker'!F11<>""),ABS('Net-loss tracker'!F11),"")) | G14: =IF('Net-loss tracker'!G8<>"",'Net-loss tracker'!G8,IF(AND(Parameters!$C$19="Percent",'Net-loss tracker'!G11<>""),ABS('Net-loss tracker'!G11),"")) | H14: =IF('Net-loss tracker'!H8<>"",'Net-loss tracker'!H8,IF(AND(Parameters!$C$19="Percent",'Net-loss tracker'!H11<>""),ABS('Net-loss tracker'!H11),"")) | I14: =IF('Net-loss tracker'!I8<>"",'Net-loss tracker'!I8,IF(AND(Parameters!$C$19="Percent",'Net-loss tracker'!I11<>""),ABS('Net-loss tracker'!I11),"")) | J14: =IF('Net-loss tracker'!J8<>"",'Net-loss tracker'!J8,IF(AND(Parameters!$C$19="Percent",'Net-loss tracker'!J11<>""),ABS('Net-loss tracker'!J11),"")) | K14: =IF('Net-loss tracker'!K8<>"",'Net-loss tracker'!K8,IF(AND(Parameters!$C$19="Percent",'Net-loss tracker'!K11<>""),ABS('Net-loss tracker'!K11),"")) | L14: =IF('Net-loss tracker'!L8<>"",'Net-loss tracker'!L8,IF(AND(Parameters!$C$19="Percent",'Net-loss tracker'!L11<>""),ABS('Net-loss tracker'!L11),"")) | ... P14: =IF('Net-loss tracker'!P8<>"",'Net-loss tracker'!P8,IF(AND(Parameters!$C$19="Percent",'Net-loss tracker'!P11<>""),ABS('Net-loss tracker'!P11),""))
A15: A10 | B15: Mix status | C15: DERIVED | D15: Empty until a reason or residual exists | E15: =IF(AND(COUNT(E6:E11)=0,E14=""),"EMPTY — do not fire a play",IF('Net-loss tracker'!E8="","PLACEHOLDER — allocating |print|, not a churn mix",IF(ABS(N(E12))>0.02*MAX(1,N(E14)),"FLAG — residual is material","OK — reasons reconcile"))) | F15: =IF(AND(COUNT(F6:F11)=0,F14=""),"EMPTY — do not fire a play",IF('Net-loss tracker'!F8="","PLACEHOLDER — allocating |print|, not a churn mix",IF(ABS(N(F12))>0.02*MAX(1,N(F14)),"FLAG — residual is material","OK — reasons reconcile"))) | G15: =IF(AND(COUNT(G6:G11)=0,G14=""),"EMPTY — do not fire a play",IF('Net-loss tracker'!G8="","PLACEHOLDER — allocating |print|, not a churn mix",IF(ABS(N(G12))>0.02*MAX(1,N(G14)),"FLAG — residual is material","OK — reasons reconcile"))) | H15: =IF(AND(COUNT(H6:H11)=0,H14=""),"EMPTY — do not fire a play",IF('Net-loss tracker'!H8="","PLACEHOLDER — allocating |print|, not a churn mix",IF(ABS(N(H12))>0.02*MAX(1,N(H14)),"FLAG — residual is material","OK — reasons reconcile"))) | I15: =IF(AND(COUNT(I6:I11)=0,I14=""),"EMPTY — do not fire a play",IF('Net-loss tracker'!I8="","PLACEHOLDER — allocating |print|, not a churn mix",IF(ABS(N(I12))>0.02*MAX(1,N(I14)),"FLAG — residual is material","OK — reasons reconcile"))) | J15: =IF(AND(COUNT(J6:J11)=0,J14=""),"EMPTY — do not fire a play",IF('Net-loss tracker'!J8="","PLACEHOLDER — allocating |print|, not a churn mix",IF(ABS(N(J12))>0.02*MAX(1,N(J14)),"FLAG — residual is material","OK — reasons reconcile"))) | K15: =IF(AND(COUNT(K6:K11)=0,K14=""),"EMPTY — do not fire a play",IF('Net-loss tracker'!K8="","PLACEHOLDER — allocating |print|, not a churn mix",IF(ABS(N(K12))>0.02*MAX(1,N(K14)),"FLAG — residual is material","OK — reasons reconcile"))) | L15: =IF(AND(COUNT(L6:L11)=0,L14=""),"EMPTY — do not fire a play",IF('Net-loss tracker'!L8="","PLACEHOLDER — allocating |print|, not a churn mix",IF(ABS(N(L12))>0.02*MAX(1,N(L14)),"FLAG — residual is material","OK — reasons reconcile"))) | ... P15: =IF(AND(COUNT(P6:P11)=0,P14=""),"EMPTY — do not fire a play",IF('Net-loss tracker'!P8="","PLACEHOLDER — allocating |print|, not a churn mix",IF(ABS(N(P12))>0.02*MAX(1,N(P14)),"FLAG — residual is material","OK — reasons reconcile")))
A17: SHARE OF DISCONNECTS (formula)
A18: ID | B18: Cause-cohort | C18: Tag | D18: Share formula | E18: Q1 2024 | F18: Q2 2024 | G18: Q3 2024 | H18: Q4 2024 | I18: Q1 2025 | J18: Q2 2025 | K18: Q3 2025 | L18: Q4 2025 | M18: Q1 2026 | N18: Q2 2026 | O18: Q3 2026 | P18: Q4 2026
A19: S1 | B19: =B6 | C19: DERIVED | D19: A1 / (A8+A7) or A7/base | E19: =IF(OR(E14="",E14=0),"",N(E6)/E14) | F19: =IF(OR(F14="",F14=0),"",N(F6)/F14) | G19: =IF(OR(G14="",G14=0),"",N(G6)/G14) | H19: =IF(OR(H14="",H14=0),"",N(H6)/H14) | I19: =IF(OR(I14="",I14=0),"",N(I6)/I14) | J19: =IF(OR(J14="",J14=0),"",N(J6)/J14) | K19: =IF(OR(K14="",K14=0),"",N(K6)/K14) | L19: =IF(OR(L14="",L14=0),"",N(L6)/L14) | ... P19: =IF(OR(P14="",P14=0),"",N(P6)/P14)
A20: S2 | B20: =B7 | C20: DERIVED | D20: A2 / (A8+A7) or A7/base | E20: =IF(OR(E14="",E14=0),"",N(E7)/E14) | F20: =IF(OR(F14="",F14=0),"",N(F7)/F14) | G20: =IF(OR(G14="",G14=0),"",N(G7)/G14) | H20: =IF(OR(H14="",H14=0),"",N(H7)/H14) | I20: =IF(OR(I14="",I14=0),"",N(I7)/I14) | J20: =IF(OR(J14="",J14=0),"",N(J7)/J14) | K20: =IF(OR(K14="",K14=0),"",N(K7)/K14) | L20: =IF(OR(L14="",L14=0),"",N(L7)/L14) | ... P20: =IF(OR(P14="",P14=0),"",N(P7)/P14)
A21: S3 | B21: =B8 | C21: DERIVED | D21: A3 / (A8+A7) or A7/base | E21: =IF(OR(E14="",E14=0),"",N(E8)/E14) | F21: =IF(OR(F14="",F14=0),"",N(F8)/F14) | G21: =IF(OR(G14="",G14=0),"",N(G8)/G14) | H21: =IF(OR(H14="",H14=0),"",N(H8)/H14) | I21: =IF(OR(I14="",I14=0),"",N(I8)/I14) | J21: =IF(OR(J14="",J14=0),"",N(J8)/J14) | K21: =IF(OR(K14="",K14=0),"",N(K8)/K14) | L21: =IF(OR(L14="",L14=0),"",N(L8)/L14) | ... P21: =IF(OR(P14="",P14=0),"",N(P8)/P14)
A22: S4 | B22: =B9 | C22: DERIVED | D22: A4 / (A8+A7) or A7/base | E22: =IF(OR(E14="",E14=0),"",N(E9)/E14) | F22: =IF(OR(F14="",F14=0),"",N(F9)/F14) | G22: =IF(OR(G14="",G14=0),"",N(G9)/G14) | H22: =IF(OR(H14="",H14=0),"",N(H9)/H14) | I22: =IF(OR(I14="",I14=0),"",N(I9)/I14) | J22: =IF(OR(J14="",J14=0),"",N(J9)/J14) | K22: =IF(OR(K14="",K14=0),"",N(K9)/K14) | L22: =IF(OR(L14="",L14=0),"",N(L9)/L14) | ... P22: =IF(OR(P14="",P14=0),"",N(P9)/P14)
A23: S5 | B23: =B10 | C23: DERIVED | D23: A5 / (A8+A7) or A7/base | E23: =IF(OR(E14="",E14=0),"",N(E10)/E14) | F23: =IF(OR(F14="",F14=0),"",N(F10)/F14) | G23: =IF(OR(G14="",G14=0),"",N(G10)/G14) | H23: =IF(OR(H14="",H14=0),"",N(H10)/H14) | I23: =IF(OR(I14="",I14=0),"",N(I10)/I14) | J23: =IF(OR(J14="",J14=0),"",N(J10)/J14) | K23: =IF(OR(K14="",K14=0),"",N(K10)/K14) | L23: =IF(OR(L14="",L14=0),"",N(L10)/L14) | ... P23: =IF(OR(P14="",P14=0),"",N(P10)/P14)
A24: S6 | B24: =B11 | C24: DERIVED | D24: A6 / (A8+A7) or A7/base | E24: =IF(OR(E14="",E14=0),"",N(E11)/E14) | F24: =IF(OR(F14="",F14=0),"",N(F11)/F14) | G24: =IF(OR(G14="",G14=0),"",N(G11)/G14) | H24: =IF(OR(H14="",H14=0),"",N(H11)/H14) | I24: =IF(OR(I14="",I14=0),"",N(I11)/I14) | J24: =IF(OR(J14="",J14=0),"",N(J11)/J14) | K24: =IF(OR(K14="",K14=0),"",N(K11)/K14) | L24: =IF(OR(L14="",L14=0),"",N(L11)/L14) | ... P24: =IF(OR(P14="",P14=0),"",N(P11)/P14)
A25: S7 | B25: =B12 | C25: DERIVED | D25: A7 / (A8+A7) or A7/base | E25: =IF(OR(E14="",E14=0),"",N(E12)/E14) | F25: =IF(OR(F14="",F14=0),"",N(F12)/F14) | G25: =IF(OR(G14="",G14=0),"",N(G12)/G14) | H25: =IF(OR(H14="",H14=0),"",N(H12)/H14) | I25: =IF(OR(I14="",I14=0),"",N(I12)/I14) | J25: =IF(OR(J14="",J14=0),"",N(J12)/J14) | K25: =IF(OR(K14="",K14=0),"",N(K12)/K14) | L25: =IF(OR(L14="",L14=0),"",N(L12)/L14) | ... P25: =IF(OR(P14="",P14=0),"",N(P12)/P14)
A27: CONTRIBUTION TO THE NET PRINT (formula)
A28: ID | B28: Cause-cohort | C28: Tag | D28: If gross adds exist, housing also shows failed-acquisition residual | E28: Q1 2024 | F28: Q2 2024 | G28: Q3 2024 | H28: Q4 2024 | I28: Q1 2025 | J28: Q2 2025 | K28: Q3 2025 | L28: Q4 2025 | M28: Q1 2026 | N28: Q2 2026 | O28: Q3 2026 | P28: Q4 2026
A29: C1 | B29: =B6 | C29: DERIVED | D29: − count (disconnects reduce the print) | E29: =IF(E6="","",-E6) | F29: =IF(F6="","",-F6) | G29: =IF(G6="","",-G6) | H29: =IF(H6="","",-H6) | I29: =IF(I6="","",-I6) | J29: =IF(J6="","",-J6) | K29: =IF(K6="","",-K6) | L29: =IF(L6="","",-L6) | ... P29: =IF(P6="","",-P6)
A30: C2 | B30: =B7 | C30: DERIVED | D30: − count (disconnects reduce the print) | E30: =IF(E7="","",-E7) | F30: =IF(F7="","",-F7) | G30: =IF(G7="","",-G7) | H30: =IF(H7="","",-H7) | I30: =IF(I7="","",-I7) | J30: =IF(J7="","",-J7) | K30: =IF(K7="","",-K7) | L30: =IF(L7="","",-L7) | ... P30: =IF(P7="","",-P7)
A31: C3 | B31: =B8 | C31: DERIVED | D31: − count (disconnects reduce the print) | E31: =IF(E8="","",-E8) | F31: =IF(F8="","",-F8) | G31: =IF(G8="","",-G8) | H31: =IF(H8="","",-H8) | I31: =IF(I8="","",-I8) | J31: =IF(J8="","",-J8) | K31: =IF(K8="","",-K8) | L31: =IF(L8="","",-L8) | ... P31: =IF(P8="","",-P8)
A32: C4 | B32: =B9 | C32: DERIVED | D32: − count (disconnects reduce the print) | E32: =IF(E9="","",-E9) | F32: =IF(F9="","",-F9) | G32: =IF(G9="","",-G9) | H32: =IF(H9="","",-H9) | I32: =IF(I9="","",-I9) | J32: =IF(J9="","",-J9) | K32: =IF(K9="","",-K9) | L32: =IF(L9="","",-L9) | ... P32: =IF(P9="","",-P9)
A33: C5 | B33: =B10 | C33: DERIVED | D33: − count (disconnects reduce the print) | E33: =IF(E10="","",-E10) | F33: =IF(F10="","",-F10) | G33: =IF(G10="","",-G10) | H33: =IF(H10="","",-H10) | I33: =IF(I10="","",-I10) | J33: =IF(J10="","",-J10) | K33: =IF(K10="","",-K10) | L33: =IF(L10="","",-L10) | ... P33: =IF(P10="","",-P10)
A34: C6 | B34: =B11 | C34: DERIVED | D34: − count (disconnects reduce the print) | E34: =IF(E11="","",-E11) | F34: =IF(F11="","",-F11) | G34: =IF(G11="","",-G11) | H34: =IF(H11="","",-H11) | I34: =IF(I11="","",-I11) | J34: =IF(J11="","",-J11) | K34: =IF(K11="","",-K11) | L34: =IF(L11="","",-L11) | ... P34: =IF(P11="","",-P11)
A35: C7 | B35: =B12 | C35: DERIVED | D35: − count (disconnects reduce the print) | E35: =IF(E12="","",-E12) | F35: =IF(F12="","",-F12) | G35: =IF(G12="","",-G12) | H35: =IF(H12="","",-H12) | I35: =IF(I12="","",-I12) | J35: =IF(J12="","",-J12) | K35: =IF(K12="","",-K12) | L35: =IF(L12="","",-L12) | ... P35: =IF(P12="","",-P12)
A38: SELECTED-QUARTER ENGINE (Dashboard feed — do not edit)
A39: # | B39: Reason | C39: Count | D39: Share | E39: Contribution | F39: Abs contrib | G39: Rank | H39: Is largest? | I39: Rest (gray) | J39: Largest (accent)
A40: 1 | B40: =B6 | C40: =IFERROR(INDEX('Attribution'!$E$6:$P$6,MATCH(Param_Quarter,'Attribution'!$E$5:$P$5,0)),"") | D40: =IF(OR(C40="",$C$47="",$C$47=0),"",C40/$C$47) | E40: =IF(C40="","",-C40) | F40: =IF(C40="",0,ABS(C40)) | G40: =IF(SUM($F$40:$F$46)=0,"",RANK(F40,$F$40:$F$46,0)) | H40: =IF(G40=1,"LARGEST","") | I40: =IF(G40=1,0,IF(C40="",NA(),C40)) | J40: =IF(G40=1,IF(C40="",NA(),C40),0)
A41: 2 | B41: =B7 | C41: =IFERROR(INDEX('Attribution'!$E$7:$P$7,MATCH(Param_Quarter,'Attribution'!$E$5:$P$5,0)),"") | D41: =IF(OR(C41="",$C$47="",$C$47=0),"",C41/$C$47) | E41: =IF(C41="","",-C41) | F41: =IF(C41="",0,ABS(C41)) | G41: =IF(SUM($F$40:$F$46)=0,"",RANK(F41,$F$40:$F$46,0)) | H41: =IF(G41=1,"LARGEST","") | I41: =IF(G41=1,0,IF(C41="",NA(),C41)) | J41: =IF(G41=1,IF(C41="",NA(),C41),0)
A42: 3 | B42: =B8 | C42: =IFERROR(INDEX('Attribution'!$E$8:$P$8,MATCH(Param_Quarter,'Attribution'!$E$5:$P$5,0)),"") | D42: =IF(OR(C42="",$C$47="",$C$47=0),"",C42/$C$47) | E42: =IF(C42="","",-C42) | F42: =IF(C42="",0,ABS(C42)) | G42: =IF(SUM($F$40:$F$46)=0,"",RANK(F42,$F$40:$F$46,0)) | H42: =IF(G42=1,"LARGEST","") | I42: =IF(G42=1,0,IF(C42="",NA(),C42)) | J42: =IF(G42=1,IF(C42="",NA(),C42),0)
A43: 4 | B43: =B9 | C43: =IFERROR(INDEX('Attribution'!$E$9:$P$9,MATCH(Param_Quarter,'Attribution'!$E$5:$P$5,0)),"") | D43: =IF(OR(C43="",$C$47="",$C$47=0),"",C43/$C$47) | E43: =IF(C43="","",-C43) | F43: =IF(C43="",0,ABS(C43)) | G43: =IF(SUM($F$40:$F$46)=0,"",RANK(F43,$F$40:$F$46,0)) | H43: =IF(G43=1,"LARGEST","") | I43: =IF(G43=1,0,IF(C43="",NA(),C43)) | J43: =IF(G43=1,IF(C43="",NA(),C43),0)
A44: 5 | B44: =B10 | C44: =IFERROR(INDEX('Attribution'!$E$10:$P$10,MATCH(Param_Quarter,'Attribution'!$E$5:$P$5,0)),"") | D44: =IF(OR(C44="",$C$47="",$C$47=0),"",C44/$C$47) | E44: =IF(C44="","",-C44) | F44: =IF(C44="",0,ABS(C44)) | G44: =IF(SUM($F$40:$F$46)=0,"",RANK(F44,$F$40:$F$46,0)) | H44: =IF(G44=1,"LARGEST","") | I44: =IF(G44=1,0,IF(C44="",NA(),C44)) | J44: =IF(G44=1,IF(C44="",NA(),C44),0)
A45: 6 | B45: =B11 | C45: =IFERROR(INDEX('Attribution'!$E$11:$P$11,MATCH(Param_Quarter,'Attribution'!$E$5:$P$5,0)),"") | D45: =IF(OR(C45="",$C$47="",$C$47=0),"",C45/$C$47) | E45: =IF(C45="","",-C45) | F45: =IF(C45="",0,ABS(C45)) | G45: =IF(SUM($F$40:$F$46)=0,"",RANK(F45,$F$40:$F$46,0)) | H45: =IF(G45=1,"LARGEST","") | I45: =IF(G45=1,0,IF(C45="",NA(),C45)) | J45: =IF(G45=1,IF(C45="",NA(),C45),0)
A46: 7 | B46: =B12 | C46: =IFERROR(INDEX('Attribution'!$E$12:$P$12,MATCH(Param_Quarter,'Attribution'!$E$5:$P$5,0)),"") | D46: =IF(OR(C46="",$C$47="",$C$47=0),"",C46/$C$47) | E46: =IF(C46="","",-C46) | F46: =IF(C46="",0,ABS(C46)) | G46: =IF(SUM($F$40:$F$46)=0,"",RANK(F46,$F$40:$F$46,0)) | H46: =IF(G46=1,"LARGEST","") | I46: =IF(G46=1,0,IF(C46="",NA(),C46)) | J46: =IF(G46=1,IF(C46="",NA(),C46),0)
...

Sheet Segments
A1: SEGMENT CUTS — WHERE and WHO overlay the reason tree
A2: PPTX: tenure · ARPU tier · exposure class (on Attribution) · rural as Scenario 3 (satellite/low-density). G1 / six-recommendation-areas also require: core vs rural Internet; AT&T ~27% / Verizon ~16% overlap vs rest (those shares are footprint mix, not losses); product mix at leave; sampled exit signal. Yellow = INPUT counts of disconnects (or net adds if labeled). Blank = not tracked.
A5: WHERE · core vs rural · overlap vs rest
A6: ID | B6: Cut | C6: Tag | D6: AT&T ~27% / Verizon ~16% = footprint mix (10-K), not a loss split | E6: Q1 2024 | F6: Q2 2024 | G6: Q3 2024 | H6: Q4 2024 | I6: Q1 2025 | J6: Q2 2025 | K6: Q3 2025 | L6: Q4 2025 | M6: Q1 2026 | N6: Q2 2026 | O6: Q3 2026 | P6: Q4 2026
A7: W1 | B7: Core | C7: INPUT | D7: Disconnect counts
A8: W2 | B8: Rural | C8: INPUT | D8: Disconnect counts
A9: W3 | B9: AT&T overlap | C9: INPUT | D9: Disconnect counts
A10: W4 | B10: Verizon overlap | C10: INPUT | D10: Disconnect counts
A11: W5 | B11: Rest of footprint | C11: INPUT | D11: Disconnect counts
B12: Sum (formula) | C12: DERIVED | D12: Should reconcile to tracker disconnects | E12: =IF(COUNT(E7:E11)=0,"",SUM(E7:E11)) | F12: =IF(COUNT(F7:F11)=0,"",SUM(F7:F11)) | G12: =IF(COUNT(G7:G11)=0,"",SUM(G7:G11)) | H12: =IF(COUNT(H7:H11)=0,"",SUM(H7:H11)) | I12: =IF(COUNT(I7:I11)=0,"",SUM(I7:I11)) | J12: =IF(COUNT(J7:J11)=0,"",SUM(J7:J11)) | K12: =IF(COUNT(K7:K11)=0,"",SUM(K7:K11)) | L12: =IF(COUNT(L7:L11)=0,"",SUM(L7:L11)) | ... P12: =IF(COUNT(P7:P11)=0,"",SUM(P7:P11))
A14: WHO · tenure at disconnect
A15: ID | B15: Cut | C15: Tag | D15: PPTX S1 skews low-tenure; S2 skews established / high-ARPU | E15: Q1 2024 | F15: Q2 2024 | G15: Q3 2024 | H15: Q4 2024 | I15: Q1 2025 | J15: Q2 2025 | K15: Q3 2025 | L15: Q4 2025 | M15: Q1 2026 | N15: Q2 2026 | O15: Q3 2026 | P15: Q4 2026
A16: N1 | B16: 0–12 months | C16: INPUT | D16: Disconnect counts
A17: N2 | B17: 12–36 months | C17: INPUT | D17: Disconnect counts
A18: N3 | B18: 36+ months | C18: INPUT | D18: Disconnect counts
B19: Sum (formula) | C19: DERIVED | D19: Should reconcile to tracker disconnects | E19: =IF(COUNT(E16:E18)=0,"",SUM(E16:E18)) | F19: =IF(COUNT(F16:F18)=0,"",SUM(F16:F18)) | G19: =IF(COUNT(G16:G18)=0,"",SUM(G16:G18)) | H19: =IF(COUNT(H16:H18)=0,"",SUM(H16:H18)) | I19: =IF(COUNT(I16:I18)=0,"",SUM(I16:I18)) | J19: =IF(COUNT(J16:J18)=0,"",SUM(J16:J18)) | K19: =IF(COUNT(K16:K18)=0,"",SUM(K16:K18)) | L19: =IF(COUNT(L16:L18)=0,"",SUM(L16:L18)) | ... P19: =IF(COUNT(P16:P18)=0,"",SUM(P16:P18))
A21: WHO · product mix at leave
A22: ID | B22: Cut | C22: Tag | D22: G1 cut. Tests whether video lock-in left and whether mobile holds | E22: Q1 2024 | F22: Q2 2024 | G22: Q3 2024 | H22: Q4 2024 | I22: Q1 2025 | J22: Q2 2025 | K22: Q3 2025 | L22: Q4 2025 | M22: Q1 2026 | N22: Q2 2026 | O22: Q3 2026 | P22: Q4 2026
A23: M1 | B23: Internet-only | C23: INPUT | D23: Disconnect counts
A24: M2 | B24: Internet + mobile | C24: INPUT | D24: Disconnect counts
A25: M3 | B25: Internet + video | C25: INPUT | D25: Disconnect counts
A26: M4 | B26: Triple-play | C26: INPUT | D26: Disconnect counts
B27: Sum (formula) | C27: DERIVED | D27: Should reconcile to tracker disconnects | E27: =IF(COUNT(E23:E26)=0,"",SUM(E23:E26)) | F27: =IF(COUNT(F23:F26)=0,"",SUM(F23:F26)) | G27: =IF(COUNT(G23:G26)=0,"",SUM(G23:G26)) | H27: =IF(COUNT(H23:H26)=0,"",SUM(H23:H26)) | I27: =IF(COUNT(I23:I26)=0,"",SUM(I23:I26)) | J27: =IF(COUNT(J23:J26)=0,"",SUM(J23:J26)) | K27: =IF(COUNT(K23:K26)=0,"",SUM(K23:K26)) | L27: =IF(COUNT(L23:L26)=0,"",SUM(L23:L26)) | ... P27: =IF(COUNT(P23:P26)=0,"",SUM(P23:P26))
A29: WHO · ARPU tier (pptx value-cohort)
A30: ID | B30: Cut | C30: Tag | D30: PPTX loss matrix = cause-cohort × value-cohort | E30: Q1 2024 | F30: Q2 2024 | G30: Q3 2024 | H30: Q4 2024 | I30: Q1 2025 | J30: Q2 2025 | K30: Q3 2025 | L30: Q4 2025 | M30: Q1 2026 | N30: Q2 2026 | O30: Q3 2026 | P30: Q4 2026
A31: V1 | B31: Low ARPU | C31: INPUT | D31: Disconnect counts
A32: V2 | B32: Mid ARPU | C32: INPUT | D32: Disconnect counts
A33: V3 | B33: High ARPU | C33: INPUT | D33: Disconnect counts
B34: Sum (formula) | C34: DERIVED | D34: Should reconcile to tracker disconnects | E34: =IF(COUNT(E31:E33)=0,"",SUM(E31:E33)) | F34: =IF(COUNT(F31:F33)=0,"",SUM(F31:F33)) | G34: =IF(COUNT(G31:G33)=0,"",SUM(G31:G33)) | H34: =IF(COUNT(H31:H33)=0,"",SUM(H31:H33)) | I34: =IF(COUNT(I31:I33)=0,"",SUM(I31:I33)) | J34: =IF(COUNT(J31:J33)=0,"",SUM(J31:J33)) | K34: =IF(COUNT(K31:K33)=0,"",SUM(K31:K33)) | L34: =IF(COUNT(L31:L33)=0,"",SUM(L31:L33)) | ... P34: =IF(COUNT(P31:P33)=0,"",SUM(P31:P33))
A36: MEASURED EXIT SIGNAL (sampled survey / port-out — not agent codes)
A37: ID | B37: Cut | C37: Tag | D37: PPTX slide 4: sample-audit codes against reality every quarter | E37: Q1 2024 | F37: Q2 2024 | G37: Q3 2024 | H37: Q4 2024 | I37: Q1 2025 | J37: Q2 2025 | K37: Q3 2025 | L37: Q4 2025 | M37: Q1 2026 | N37: Q2 2026 | O37: Q3 2026 | P37: Q4 2026
A38: X1 | B38: Price | C38: INPUT | D38: Disconnect counts
A39: X2 | B39: Speed / reliability / upload | C39: INPUT | D39: Disconnect counts
A40: X3 | B40: Move-out | C40: INPUT | D40: Disconnect counts
A41: X4 | B41: Non-pay | C41: INPUT | D41: Disconnect counts
A42: X5 | B42: Other / unknown | C42: INPUT | D42: Disconnect counts
B43: Sum (formula) | C43: DERIVED | D43: Should reconcile to tracker disconnects | E43: =IF(COUNT(E38:E42)=0,"",SUM(E38:E42)) | F43: =IF(COUNT(F38:F42)=0,"",SUM(F38:F42)) | G43: =IF(COUNT(G38:G42)=0,"",SUM(G38:G42)) | H43: =IF(COUNT(H38:H42)=0,"",SUM(H38:H42)) | I43: =IF(COUNT(I38:I42)=0,"",SUM(I38:I42)) | J43: =IF(COUNT(J38:J42)=0,"",SUM(J38:J42)) | K43: =IF(COUNT(K38:K42)=0,"",SUM(K38:K42)) | L43: =IF(COUNT(L38:L42)=0,"",SUM(L38:L42)) | ... P43: =IF(COUNT(P38:P42)=0,"",SUM(P38:P42))
A45: OPTIONAL BEGIN PSUs FOR RATES (WHERE)
A46: ID | B46: Cut | C46: Tag | D46: Beginning residential Internet PSUs in this cut | E46: Q1 2024 | F46: Q2 2024 | G46: Q3 2024 | H46: Q4 2024 | I46: Q1 2025 | J46: Q2 2025 | K46: Q3 2025 | L46: Q4 2025 | M46: Q1 2026 | N46: Q2 2026 | O46: Q3 2026 | P46: Q4 2026
A47: B1 | B47: Core begin | C47: INPUT | D47: Needed for a rate, not just a share
...

Sheet Parameters
A1: PARAMETERS
A2: Yellow = INPUT. Blue fill = ESTIMATED template default the user can change. PPTX slide 5: ≥40% dominant · 25–40% mixed · <25% null. FWA signal >35–40%. Thresholds are judgment calls, set in advance (pptx notes: arbitrary-but-stated beats unstated).
A4: ID | B4: Parameter | C4: Value | D4: Tag | E4: Source / why it is here
A5: P1 | B5: Selected quarter | C5: Q1 2026 | D5: INPUT | E5: Assignment anchor is Q1 2026. Q2 is a later public fact (pptx + six-recommendation-areas).
A6: P2 | B6: Reason taxonomy | C6: PPTX 6-scenario | D6: INPUT | E6: PPTX scenarios 1–6. Alternate label only — codes stay R1–R4 + satellite + residual.
A7: P3 | B7: Highlight color (tables) | C7: 2E75B6 | D7: INPUT | E7: One accent. Charts use this hex for the story series; peers stay gray.
A8: P4 | B8: Dominant-driver threshold | C8: 0.4 | D8: ESTIMATED | E8: PPTX slide 5: one cause-cohort ≥40% of quarterly losses → fire that lead play at scale.
A9: P5 | B9: Mixed-picture floor | C9: 0.25 | D9: ESTIMATED | E9: PPTX slide 5: 25–40% mixed (top two as experiments). <25% → Scenario 6 null.
A10: P6 | B10: FWA scenario trigger | C10: 0.35 | D10: ESTIMATED | E10: PPTX S1: FWA-covered losses >35–40%; skew low-tenure / low-ARPU; exit cites price.
A11: P7 | B11: Fiber scenario trigger | C11: 0.4 | D11: ESTIMATED | E11: PPTX S2: fiber-DMA losses dominate; high-ARPU; exit cites speed / reliability / upload.
A12: P8 | B12: Satellite scenario trigger | C12: 0.25 | D12: ESTIMATED | E12: PPTX S3: losses map to satellite-only low-density blocks. No numeric cut in the deck — template default.
A13: P9 | B13: Co-equal band (pp of mix) | C13: 0.05 | D13: ESTIMATED | E13: GAP: co-equal cells fire the cheaper lever first. Two expensive levers do not fire in the same quarter.
A14: P10 | B14: Core-drives-print share | C14: 0.7 | D14: ESTIMATED | E14: WHERE overlay (decisions.md W1): if core is the Internet leak, fire the reason play on the core — do not add rural miles.
A15: P11 | B15: Segment rate-skew vs company | C15: 1.5 | D15: ESTIMATED | E15: Flag a segment whose net-loss rate is ≥ this multiple of the company residential rate.
A16: P12 | B16: Require two consecutive quarters before full-scale? | C16: Yes | D16: ESTIMATED | E16: PPTX slide 11 risk interlock: thresholds require two consecutive quarters before full-scale (experiments can start on one).
A17: P13 | B17: Tracker already exists and is used quarterly? | C17: No — fill G1 first | D17: INPUT | E17: Kill rule 1 (six-recommendation-areas / decisions.md): if yes, skip Area 1 build and go to mix control.
A18: P14 | B18: Use Comcast benchmark? | C18: Yes | D18: INPUT | E18: Apples-to-apples is residential broadband (CHTR res. Internet vs CMCSA domestic resid. BB).
A19: P15 | B19: Attribution input mode | C19: Counts | D19: INPUT | E19: Counts (preferred) = sampled disconnects. Percent allocates the selected base — not a measured rate.
A20: P16 | B20: If only % is filled, allocate against | C20: Disconnects (if known), else |public print| | D20: ESTIMATED | E20: Playbook: do not invent a mix. Allocating the net print is a PLACEHOLDER, not a churn rate.
A21: P17 | B21: Material share of peer excess | C21: 0.25 | D21: ESTIMATED | E21: GAP: a branch fires only if it is largest/co-equal AND closing the Comcast gap in that cell would absorb a material share of the excess.
A22: P18 | B22: Playbook committed excess (customers) | C22: 54000 | D22: RETRIEVED | E22: six-recommendation-areas.md / network_churn_model.py: 54k (round down from 54.4k) · 1.8× Comcast. Q1 identity only. Not in the pptx.
A24: REASON TAXONOMY (edit labels — codes stay fixed)
A25: Code | B25: Dashboard label (INPUT) | C25: PPTX scenario | D25: GAP branch | E25: Lead play (do not fire from empty cells)
A26: R-FWA | B26: Competitive FWA | C26: S1 FWA-driven | D26: R2 | E26: Convergence pricing / FWA-match in FWA zones; economics gate on MVNO unit cost.
A27: R-FIB | B27: Competitive fiber (overbuild) | C27: S2 Fiber-driven | D27: R3 | E27: Re-sequence DOCSIS 4.0 by exposure + symmetric win-back. Node-split only if sample names speed.
A28: R-SAT | B28: LEO satellite | C28: S3 Satellite-driven | D28: W2 overlay | E28: Accelerate rural subsidized activation ahead of Starlink/Kuiper. Honor RDOF/BEAD.
A29: R-MOV | B29: Move-out / housing | C29: S4 Housing-driven | D29: R1 | E29: Mover capture: Community Solutions / MDU / instant-on. Not a save-offer problem.
A30: R-NPY | B30: Non-pay / economic | C30: S5 Non-pay | D30: R4 | E30: Payment arrangement / value tier at delinquency. Funded by care opex if this is the leak.
A31: R-OTH | B31: Service / other | C31: Residual | D31: — | E31: Unmapped residual. If this is largest, the sample is incomplete — do not fire a plant program.
A33: Dropdown lists (do not edit structure)
A34: Q1 2024 | B34: Yes | C34: Yes — skip Area 1 build | D34: Counts | E34: PPTX 6-scenario
A35: Q2 2024 | B35: No | C35: No — fill G1 first | D35: Percent | E35: GAP R1–R4 only
A36: Q3 2024
A37: Q4 2024
A38: Q1 2025
A39: Q2 2025
A40: Q3 2025
A41: Q4 2025
A42: Q1 2026
A43: Q2 2026
...

Sheet Assumptions
A1: ASSUMPTION REGISTER · one line per input
A2: Solving playbook: one assumption per line with a line ID; derived lines are formulas. Tag every input RETRIEVED or INPUT (user-entered). Thresholds are ESTIMATED template defaults. Dollar-weight is not meaningful until Attribution is filled — then the mix is 100% INPUT.
A5: ID | B5: Line | C5: Value / pointer | D5: Tag | E5: Origin | F5: Formula or citation | G5: Confidence
A6: T1 | B6: Beginning res. Internet PSUs by quarter | C6: Net-loss tracker!E6:P6 | D6: RETRIEVED / INPUT | E6: Ex99.1 trending EOP identity; overwrite if internal | F6: Prior EOP. Q1 2026 = 27,641,000 | G6: High where green
A7: T2 | B7: Gross adds | C7: Net-loss tracker!E7:P7 | D7: INPUT | E7: Internal billing | F7: Blank until filled | G7: —
A8: T3 | B8: Disconnects | C8: Net-loss tracker!E8:P8 | D8: INPUT | E8: Sampled disconnect file, not agent codes | F8: Blank until filled | G8: —
A9: T4 | B9: Internal net | C9: Net-loss tracker!E9:P9 | D9: DERIVED | E9: T2 - T3 | F9: =gross-disconnects | G9: Formula
A10: T5 | B10: Public res. Internet print | C10: Net-loss tracker!E10:P10 | D10: RETRIEVED | E10: CHTR Ex99.1 / Q1 2026 trending | F10: Q1 2026 -117,000 · Q2 2026 -166,000 | G10: High
A11: T6 | B11: Print used | C11: Net-loss tracker!E11:P11 | D11: DERIVED | E11: T4 if both internals filled, else T5 | F11: IF(T4<>"",T4,T5) | G11: Formula
A12: T7 | B12: Company Internet print | C12: Net-loss tracker!E12:P12 | D12: RETRIEVED | E12: Ex99.1 total Internet | F12: Q1 -120,000 · Q2 -172,000 — context, not T6 | G12: High
A13: T8 | B13: Rural CR adds | C13: Net-loss tracker!E13:P13 | D13: RETRIEVED | E13: Ex99.1 rural-footprint CR | F13: Q1 +41,000 · Q2 +47,000 — NOT an Internet cut | G13: High / wrong unit
A14: T9 | B14: CMCSA resid. BB net adds | C14: Net-loss tracker!E14:P14 | D14: RETRIEVED / INPUT | E14: CMCSA Ex99.1 Q1 2026; other qtrs INPUT | F14: Q1 2026 -65,000 | G14: High for Q1
A15: T10 | B15: CMCSA begin PSUs | C15: Net-loss tracker!E15:P15 | D15: RETRIEVED / INPUT | E15: 28,654k EOP - (-65k) | F15: Q1 2026 28,719,000 | G15: High for Q1
A16: T11 | B16: CMCSA net-loss rate | C16: Net-loss tracker!E16:P16 | D16: DERIVED | E16: |T9|/T10 | F16: Q1 ~ 0.226% | G16: Formula
A17: T12 | B17: CHTR res. net-loss rate | C17: Net-loss tracker!E17:P17 | D17: DERIVED | E17: |T6|/T1 | F17: Q1 ~ 0.423% | G17: Formula
A18: T13 | B18: Rate ratio | C18: Net-loss tracker!E18:P18 | D18: DERIVED | E18: T12/T11 | F18: Unrounded ~1.87x; commit 1.8x | G18: Formula
A19: T14 | B19: Expected losses at peer rate | C19: Net-loss tracker!E19:P19 | D19: DERIVED | E19: T11*T1 | F19: Q1 ~ 62.6k | G19: Formula
A20: T15 | B20: Excess vs Comcast | C20: Net-loss tracker!E20:P20 | D20: DERIVED | E20: |T6|-T14 | F20: Q1 ~ 54.4k; P18 commits 54,000 (six-recommendation-areas.md) | G20: Formula
A21: P18 | B21: Playbook committed excess | C21: Parameters!C22 | D21: RETRIEVED | E21: six-recommendation-areas.md / network_churn_model.py — not the pptx | F21: 54,000 customers | G21: Commit / round down
... A38: P12 | B38: Two-quarter interlock | C38: Parameters!C16 | D38: ESTIMATED | E38: PPTX slide 11 | F38: Yes | G38: Template default
A40: WEIGHT
A41: W1 | B41: Count of register lines by tag (this template, before a fill) | C41: =COUNTIF(D6:D38,"RETRIEVED")&" RETRIEVED · "&COUNTIF(D6:D38,"INPUT")&" INPUT · "&COUNTIF(D6:D38,"ESTIMATED")&" ESTIMATED · "&COUNTIF(D6:D38,"DERIVED")&" DERIVED"
A42: W2 | B42: Dollar-weighted once Attribution is filled | C42: =IF(Attribution!C49="No","Not meaningful — mix is empty. Do not quote a retrieved % of a mix that does not exist.","Once filled, 100% of the reason mix is INPUT (sampled disconnects). Public prints do not validate the mix.")

Sheet Playbook
A1: PLAYBOOK ON A PAGE · reference only — does not fire from empty cells
A2: PPTX slides 6-9 (scenarios 1-6) plus GAP R1-R4 / WHERE overlays from decisions.md. Budgets and owners are pre-authorized in the deck, not sized here. Dashboard routes a scenario; this sheet is the leave-behind.
A5: # | B5: Trigger (signal) | C5: Lead play | D5: Economics gate | E5: Proof | F5: Kill | G5: Fallback
A6: S1 | B6: FWA-covered losses >35-40%; low-tenure / low-ARPU; audited exit cites price. | C6: Convergence pricing attack: internet + unlimited mobile at/below T-Mobile Home Internet, FWA-exposed zones only. | D6: Bundle discount < churn-avoided LTV. Needs MVNO wholesale cost/line (pptx open item). | E6: Churn delta, treated vs untreated FWA zones, 2 quarters, pre-registered. | F6: No churn separation after 2 quarters, or bundle margin negative after CBRS-offload. | G6: Value flanker tier — or concede the segment and route budget to S2/S6.
A7: S2 | B7: Losses skew to AT&T/Verizon/Frontier fiber DMAs; higher-ARPU; exit cites speed / reliability / upload. | C7: Re-sequence DOCSIS 4.0 / high-split by competitive exposure (not construction cost) + symmetric win-back. | D7: Re-sequencing premium vs LTV at risk. End-2027 completion is the binding constraint to test — not the closer. | E7: Churn in evolution-complete vs incomplete overbuilt zones (cleanest natural experiment). | F7: Parity product, continued losses — completed zones bleed at the same rate. | G7: Harvest, don't chase: stop defending unwinnable zones at full cost.
A8: S3 | B8: Losses map to low-density census blocks where Starlink (Kuiper next) is the only alternative. | C8: Accelerate rural subsidized build activation — penetrate new passings before satellite entrenches. | D8: Program already funded; variable is activation pace vs BEAD/RDOF milestone penalties. | E8: Penetration on new rural passings vs vintage cohorts. Rural CR already +41k Q1 / +47k Q2 (wrong unit for Internet). | F8: Penetration on new passings falls below the underwriting curve. | G8: Slow non-committed rural extensions; subsidy-committed builds continue.
A9: S4 | B9: Gross adds down, competitor churn flat; disconnects cluster on move-outs; losses spread across exposure classes. | C9: No attacker to fight. Mover capture: Community Solutions / MDU / instant-on self-install. | D9: Mover-capture cost per connect vs standard acquisition; MDU deals building-by-building. | E9: Connect share of new move-ins; gross-add recovery as housing turnover normalizes. | F9: Port-out destination data contradicts the macro story -> re-route to S1-S2. | G9: Disclose losses by cohort so the multiple stops pricing macro softness as share loss.
A10: S5 | B10: Losses skew to non-pay / downgrades; ACP-echo demographics. FY2025 60+ day delinquencies improved (~82k vs ~103k) — size before funding. | C10: Retention-priced value tier with credit-friendly terms at the point of delinquency. | D10: Save-rate x retained margin vs discount cost + bad-debt exposure. | E10: Save-rate on treated delinquent accounts vs control; 6-month survival. | F10: Save-rate economics below LTV — then let it churn. | G10: None — self-limiting.
A11: S6 | B11: No cause-cohort exceeds ~25-30% of losses. Plausibly the true state of the world. | C11: Change-what-the-market-prices track: re-segment disclosure (rural vs core), post-2027 capex guidance, plus spend-capped experiments from S1-S3. | D11: Disclosure costs ~nothing; experiments are spend-capped. | E11: Multiple response to disclosure; experiment read-outs feed the next cycle. | F11: A later quarter crosses a threshold -> that scenario fires. Null is a state, not a verdict. | G11: Not applicable — S6 is the floor.
A13: GAP overlay (does not replace S1-S6)
A14: R1-R4 | B14: If lost to move-out -> TOS/MDU (6 months). FWA -> 12-month rate-lock on and off overlap (hand on-overlap FWA to fiber if it is a stepping-stone). Fiber -> overlap-zip gig/symmetry; node-split only if the sample names speed. Nonpay -> payment arrangement / 90-day first-bill save. WHERE: fire on the core; do not add rural miles. WHO (mix/tenure) sizes the offer — it is not a fifth spend program. Funding: named pools P1-P4 only. Never two expensive levers in the same quarter.
A16: Timeline | B16: PPTX slide 10: Q+1 sensor live · Q+2 first attribution read · Q+3 plays trigger · Q+4-5 proof or kill. six-recommendation-areas: G1 question this week; first fill in one quarter; reason-play 2-4 quarters after fill.
